{
 "cells": [
  {
   "cell_type": "code",
   "execution_count": 1,
   "id": "c2fac98b",
   "metadata": {},
   "outputs": [],
   "source": [
    "import cv2"
   ]
  },
  {
   "cell_type": "code",
   "execution_count": 2,
   "id": "c30e846d",
   "metadata": {},
   "outputs": [],
   "source": [
    "import matplotlib.pyplot as plt"
   ]
  },
  {
   "cell_type": "code",
   "execution_count": 4,
   "id": "7b3c2723",
   "metadata": {},
   "outputs": [
    {
     "name": "stdout",
     "output_type": "stream",
     "text": [
      "Collecting matplotlib\n",
      "  Using cached matplotlib-3.5.0-cp37-cp37m-win_amd64.whl (7.2 MB)\n",
      "Requirement already satisfied: pyparsing>=2.2.1 in c:\\anaconda\\envs\\ten\\lib\\site-packages (from matplotlib) (2.4.7)\n",
      "Requirement already satisfied: cycler>=0.10 in c:\\anaconda\\envs\\ten\\lib\\site-packages (from matplotlib) (0.11.0)\n",
      "Requirement already satisfied: fonttools>=4.22.0 in c:\\anaconda\\envs\\ten\\lib\\site-packages (from matplotlib) (4.28.2)\n",
      "Note: you may need to restart the kernel to use updated packages.Requirement already satisfied: numpy>=1.17 in c:\\anaconda\\envs\\ten\\lib\\site-packages (from matplotlib) (1.20.2)\n"
     ]
    },
    {
     "name": "stderr",
     "output_type": "stream",
     "text": [
      "Error processing line 1 of C:\\Users\\Ahmed Sabry Tamam\\AppData\\Roaming\\Python\\Python37\\site-packages\\matplotlib-3.5.0-py3.7-nspkg.pth:\n",
      "\n",
      "  Traceback (most recent call last):\n",
      "    File \"C:\\anaconda\\envs\\ten\\lib\\site.py\", line 168, in addpackage\n",
      "      exec(line)\n",
      "    File \"<string>\", line 1, in <module>\n",
      "    File \"<frozen importlib._bootstrap>\", line 580, in module_from_spec\n",
      "  AttributeError: 'NoneType' object has no attribute 'loader'\n",
      "\n",
      "Remainder of file ignored\n",
      "Error processing line 1 of C:\\anaconda\\envs\\ten\\lib\\site-packages\\matplotlib-3.5.0-py3.7-nspkg.pth:\n",
      "\n",
      "  Traceback (most recent call last):\n",
      "    File \"C:\\anaconda\\envs\\ten\\lib\\site.py\", line 168, in addpackage\n",
      "      exec(line)\n",
      "    File \"<string>\", line 1, in <module>\n",
      "    File \"<frozen importlib._bootstrap>\", line 580, in module_from_spec\n",
      "  AttributeError: 'NoneType' object has no attribute 'loader'\n",
      "\n",
      "Remainder of file ignored\n"
     ]
    },
    {
     "name": "stdout",
     "output_type": "stream",
     "text": [
      "\n",
      "Requirement already satisfied: setuptools-scm>=4 in c:\\anaconda\\envs\\ten\\lib\\site-packages (from matplotlib) (6.3.2)\n",
      "Requirement already satisfied: packaging>=20.0 in c:\\anaconda\\envs\\ten\\lib\\site-packages (from matplotlib) (20.9)\n",
      "Requirement already satisfied: python-dateutil>=2.7 in c:\\anaconda\\envs\\ten\\lib\\site-packages (from matplotlib) (2.8.1)\n",
      "Requirement already satisfied: kiwisolver>=1.0.1 in c:\\anaconda\\envs\\ten\\lib\\site-packages (from matplotlib) (1.3.2)\n",
      "Requirement already satisfied: pillow>=6.2.0 in c:\\anaconda\\envs\\ten\\lib\\site-packages (from matplotlib) (8.2.0)\n",
      "Requirement already satisfied: six>=1.5 in c:\\anaconda\\envs\\ten\\lib\\site-packages (from python-dateutil>=2.7->matplotlib) (1.16.0)\n",
      "Requirement already satisfied: tomli>=1.0.0 in c:\\anaconda\\envs\\ten\\lib\\site-packages (from setuptools-scm>=4->matplotlib) (1.2.2)\n",
      "Requirement already satisfied: setuptools in c:\\anaconda\\envs\\ten\\lib\\site-packages (from setuptools-scm>=4->matplotlib) (52.0.0.post20210125)\n",
      "Installing collected packages: matplotlib\n",
      "Successfully installed matplotlib-3.5.0\n"
     ]
    }
   ],
   "source": [
    "pip install --user  matplotlib"
   ]
  },
  {
   "cell_type": "code",
   "execution_count": 12,
   "id": "f0f5014e",
   "metadata": {},
   "outputs": [],
   "source": [
    "con = \"ssd_mobilenet_v3_large_coco_2020_01_14.pbtxt\"\n",
    "f = \"frozen_inference_graph.pb\""
   ]
  },
  {
   "cell_type": "code",
   "execution_count": 13,
   "id": "20793ccd",
   "metadata": {},
   "outputs": [
    {
     "ename": "SystemError",
     "evalue": "<class 'cv2.dnn_DetectionModel'> returned a result with an error set",
     "output_type": "error",
     "traceback": [
      "\u001b[1;31m---------------------------------------------------------------------------\u001b[0m",
      "\u001b[1;31merror\u001b[0m                                     Traceback (most recent call last)",
      "\u001b[1;31merror\u001b[0m: OpenCV(4.5.4) D:\\a\\opencv-python\\opencv-python\\opencv\\modules\\dnn\\src\\caffe\\caffe_io.cpp:1138: error: (-2:Unspecified error) FAILED: fs.is_open(). Can't open \"frozen_inference_graph.pb\" in function 'cv::dnn::ReadProtoFromBinaryFile'\n",
      "\nThe above exception was the direct cause of the following exception:\n",
      "\u001b[1;31mSystemError\u001b[0m                               Traceback (most recent call last)",
      "\u001b[1;32m<ipython-input-13-a1f98fd53b61>\u001b[0m in \u001b[0;36m<module>\u001b[1;34m\u001b[0m\n\u001b[1;32m----> 1\u001b[1;33m \u001b[0mmodule\u001b[0m \u001b[1;33m=\u001b[0m \u001b[0mcv2\u001b[0m\u001b[1;33m.\u001b[0m\u001b[0mdnn_DetectionModel\u001b[0m\u001b[1;33m(\u001b[0m\u001b[0mf\u001b[0m\u001b[1;33m,\u001b[0m\u001b[0mcon\u001b[0m\u001b[1;33m)\u001b[0m\u001b[1;33m\u001b[0m\u001b[1;33m\u001b[0m\u001b[0m\n\u001b[0m",
      "\u001b[1;31mSystemError\u001b[0m: <class 'cv2.dnn_DetectionModel'> returned a result with an error set"
     ]
    }
   ],
   "source": [
    "module = cv2.dnn_DetectionModel(f,con)"
   ]
  },
  {
   "cell_type": "code",
   "execution_count": 5,
   "id": "471ae488",
   "metadata": {},
   "outputs": [
    {
     "ename": "SyntaxError",
     "evalue": "invalid syntax (<ipython-input-5-4c84a3c7ea0f>, line 4)",
     "output_type": "error",
     "traceback": [
      "\u001b[1;36m  File \u001b[1;32m\"<ipython-input-5-4c84a3c7ea0f>\"\u001b[1;36m, line \u001b[1;32m4\u001b[0m\n\u001b[1;33m    casslabels = fpt.read()rstrip(\"\\n\").split(\"\\n\")\u001b[0m\n\u001b[1;37m                                ^\u001b[0m\n\u001b[1;31mSyntaxError\u001b[0m\u001b[1;31m:\u001b[0m invalid syntax\n"
     ]
    }
   ],
   "source": [
    "casslabels = []\n",
    "file_name = \"lables.txt\"\n",
    "with open(file_name,\"rt\")as fpt :\n",
    "    casslabels = fpt.read()rstrip(\"\\n\").split(\"\\n\")\n",
    "    \n"
   ]
  },
  {
   "cell_type": "code",
   "execution_count": null,
   "id": "1b8b6bdb",
   "metadata": {},
   "outputs": [],
   "source": [
    "\n",
    "print(len(casslabels))"
   ]
  }
 ],
 "metadata": {
  "kernelspec": {
   "display_name": "Python 3",
   "language": "python",
   "name": "python3"
  },
  "language_info": {
   "codemirror_mode": {
    "name": "ipython",
    "version": 3
   },
   "file_extension": ".py",
   "mimetype": "text/x-python",
   "name": "python",
   "nbconvert_exporter": "python",
   "pygments_lexer": "ipython3",
   "version": "3.7.10"
  }
 },
 "nbformat": 4,
 "nbformat_minor": 5
}
